Workbook

Sheet ข้อมูลลูกค้า
A1: รอบบัญชี | C1: ตัวอย่างข้อมูลที่กรอก
A2: ชื่อ
A3: ประเภทกิจการ | C3: ห้างหุ้นส่วนจำกัด | D3: บริษัทจำกัด | E3: นิติบุคคลอาคารชุด | F3: นิติบุคคลหมู่บ้านจัดสรร | G3: มูลนิธิ
A4: ที่อยู่
A5: เลขประจำตัวผู้เสียภาษี
A6: ประเภทธุรกิจ
A7: วันอนุมัติ
A8: วันจัดตั้ง
A9: วันต้นงวด
A10: วันสิ้นงวด
A11: วันต้นงวด(ของปีเก่า)
A12: วันสิ้นงวด(ของปีเก่า)
A13: กรรมการ1
A14: กรรมการ2
A15: กรรมการ3
... A26: ตรวจสอบตั้งแต่วันที่
A27: ถึงวันที่ | B27: =+B26
A28: ค่าตรวจสอบบัญชี
A29: จำนวนชั่วโมง
A30: ประมาณการค่าใช้จ่าย
A31: วิธีที่ใช้ในการตรวจสอบ | B31: ตรวจสอบเนื้อหาสาระ | C31: ตรวจสอบเนื้อหาสาระ
C32: ทดสอบระบบการควบคุมภายใน
A33: เนื่องจาก | B33: กิจการว่าจ้างผู้ทำบัญชีภายนอก เพื่อบันทึกบัญชีและจัดทำงบการเงิน
A37: คาดการณ์งบประมาณในการตรวจสอบ | B37: =+B30
A39: วันที่ในหนังสือรับรองข้อมูล
A41: ผู้ใช้งบการเงิน | B41: กรรมการ เจ้าของกิจการ ผู้ถือหุ้น
B42: ธนาคาร
B43: หน่วยงานราชการ เช่น กรมสรรพากร กรมพัฒนาธุรกิจการค้า
A45: ระดับความมีสาระสำคัญ
A46: กำหนดจาก | C46: สินทรัพย์รวม | D46: ทุนรวม | E46: กำไรสุทธิ | F46: รายได้รวม
A47: เนื่องจาก
A48: ช่วงเวลาของจำนวนที่ใช้เป็นฐาน | C48: ณ วันที่ | D48: ตั้งแต่วันที่
A49: จำนวนที่ใช้เป็นฐาน
A50: อัตราที่ใช้หา OM | B50: 0.02
A51: อัตราที่ใช้หา PM | B51: 0.75
A52: เนื่องจาก | B52: มีความเสี่ยงในระดับปานกลาง
A53: อัตราที่ใช้หา AM | B53: 0.1
A54: เนื่องจาก
A56: สภาพแวดล้อมของกิจการ
A59: การเปลี่ยนแปลงที่สำคัญของกิจการ | B59: ไม่มี
...

Sheet ประเภทบัญชี
A1: Working Paper | B1: รายการบัญชี | C1: ชื่อหัวข้อบัญชี | D1: ประเภทบัญชี | E1: ประเภทในรายงาน | F1: งบการเงิน | G1: nature | H1: ค่าบวกลบ | I1: ค่าบวกลบในรายงาน
A2: A | B2: เงินสดและรายการเทียบเท่าเงินสด > เงินสด | C2: เงินสดและรายการเทียบเท่าเงินสด | D2: สินทรัพย์หมุนเวียน | E2: สินทรัพย์ | F2: งบดุล | G2: เดบิต | H2: 1 | I2: 1
A3: A | B3: เงินสดและรายการเทียบเท่าเงินสด > เงินฝากกระแสรายวัน | C3: เงินสดและรายการเทียบเท่าเงินสด | D3: สินทรัพย์หมุนเวียน | E3: สินทรัพย์ | F3: งบดุล | G3: เดบิต | H3: 1 | I3: 1
A4: A | B4: เงินสดและรายการเทียบเท่าเงินสด > เงินฝากออมทรัพย์ | C4: เงินสดและรายการเทียบเท่าเงินสด | D4: สินทรัพย์หมุนเวียน | E4: สินทรัพย์ | F4: งบดุล | G4: เดบิต | H4: 1 | I4: 1
A5: A | B5: เงินสดและรายการเทียบเท่าเงินสด > เงินฝากประจำที่ครบกำหนดใน 3 เดือน | C5: เงินสดและรายการเทียบเท่าเงินสด | D5: สินทรัพย์หมุนเวียน | E5: สินทรัพย์ | F5: งบดุล | G5: เดบิต | H5: 1 | I5: 1
A6: A | B6: เงินสดและรายการเทียบเท่าเงินสด > ตั๋วเงินฝาก | C6: เงินสดและรายการเทียบเท่าเงินสด | D6: สินทรัพย์หมุนเวียน | E6: สินทรัพย์ | F6: งบดุล | G6: เดบิต | H6: 1 | I6: 1
A7: A | B7: เงินสดและรายการเทียบเท่าเงินสด > ตราสารอื่นๆ | C7: เงินสดและรายการเทียบเท่าเงินสด | D7: สินทรัพย์หมุนเวียน | E7: สินทรัพย์ | F7: งบดุล | G7: เดบิต | H7: 1 | I7: 1
A8: B | B8: เงินลงทุนชั่วคราว (ราคาทุน) | C8: เงินลงทุนชั่วคราว | D8: สินทรัพย์หมุนเวียน | E8: สินทรัพย์ | F8: งบดุล | G8: เดบิต | H8: 1 | I8: 1
A9: B | B9: เงินลงทุนชั่วคราว (ค่าเผื่อการด้อยค่าของเงินลงทุน) | C9: เงินลงทุนชั่วคราว | D9: สินทรัพย์หมุนเวียน | E9: สินทรัพย์ | F9: งบดุล | G9: เดบิต | H9: -1 | I9: 1
A10: C | B10: ลูกหนี้การค้า (ราคาทุน) | C10: ลูกหนี้การค้าและลูกหนี้อื่นๆ | D10: สินทรัพย์หมุนเวียน | E10: สินทรัพย์ | F10: งบดุล | G10: เดบิต | H10: 1 | I10: 1
A11: C | B11: ลูกหนี้การค้า (ค่าเผื่อหนี้สงสัยจะสูญ) | C11: ลูกหนี้การค้าและลูกหนี้อื่นๆ | D11: สินทรัพย์หมุนเวียน | E11: สินทรัพย์ | F11: งบดุล | G11: เดบิต | H11: -1 | I11: 1
A12: C | B12: ลูกหนี้อื่นๆ (ราคาทุน) | C12: ลูกหนี้การค้าและลูกหนี้อื่นๆ | D12: สินทรัพย์หมุนเวียน | E12: สินทรัพย์ | F12: งบดุล | G12: เดบิต | H12: 1 | I12: 1
A13: C | B13: ลูกหนี้อื่นๆ (ค่าเผื่อหนี้สงสัยจะสูญ) | C13: ลูกหนี้การค้าและลูกหนี้อื่นๆ | D13: สินทรัพย์หมุนเวียน | E13: สินทรัพย์ | F13: งบดุล | G13: เดบิต | H13: -1 | I13: 1
... A84: LL | B84: หนี้สินไม่หมุนเวียนอื่น | C84: หนี้สินไม่หมุนเวียนอื่น | D84: หนี้สินไม่หมุนเวียน | E84: หนี้สินและส่วนของผู้ถือหุ้น | F84: งบดุล | G84: เครดิต | H84: 1 | I84: 1
A85: NULL | B85: ทุนเรือนหุ้น > ทุนจดทะเบียน > หุ้นสามัญ | C85: ทุนเรือนหุ้น > ทุนจดทะเบียน > หุ้นสามัญ | I85: 1
A86: NN | B86: ทุนเรือนหุ้น > ทุนที่ชำระแล้ว > หุ้นสามัญ | C86: ทุนเรือนหุ้น > ทุนที่ชำระแล้ว > หุ้นสามัญ | D86: ส่วนของผู้ถือหุ้น | E86: หนี้สินและส่วนของผู้ถือหุ้น | F86: งบดุล | G86: เครดิต | H86: 1 | I86: 1
A87: OO | B87: ส่วนเกินมูลค่าหุ้น | C87: ส่วนเกินมูลค่าหุ้น | D87: ส่วนของผู้ถือหุ้น | E87: หนี้สินและส่วนของผู้ถือหุ้น | F87: งบดุล | G87: เครดิต | H87: 1 | I87: 1
A88: PP | B88: กำไรสุทธิ ของงวด | C88: กำไรสะสม | D88: ส่วนของผู้ถือหุ้น | E88: หนี้สินและส่วนของผู้ถือหุ้น | F88: งบดุล | G88: เครดิต | H88: 1 | I88: 1
A89: PP | B89: กำไรสะสมยกมา | C89: กำไรสะสม | D89: ส่วนของผู้ถือหุ้น | E89: หนี้สินและส่วนของผู้ถือหุ้น | F89: งบดุล | G89: เครดิต | H89: 1 | I89: 1
A90: PP | B90: ขาดทุนสุทธิ ของงวด | C90: ขาดทุนสะสม | D90: ส่วนของผู้ถือหุ้น | E90: หนี้สินและส่วนของผู้ถือหุ้น | F90: งบดุล | G90: เครดิต | H90: -1 | I90: 1
A91: PP | B91: ขาดทุนสะสมยกมา | C91: ขาดทุนสะสม | D91: ส่วนของผู้ถือหุ้น | E91: หนี้สินและส่วนของผู้ถือหุ้น | F91: งบดุล | G91: เครดิต | H91: -1 | I91: 1
A92: QQ | B92: องค์ประกอบอื่นของส่วนของผู้ถือหุ้น | C92: องค์ประกอบอื่นของส่วนของผู้ถือหุ้น | D92: ส่วนของผู้ถือหุ้น | E92: หนี้สินและส่วนของผู้ถือหุ้น | F92: งบดุล | G92: เครดิต | H92: 1 | I92: 1
A93: 10 | B93: รายได้จากการขายหรือการให้บริการ | C93: รายได้จากการขายหรือการให้บริการ | D93: รายได้ | E93: รายได้และค่าใช้จ่าย | F93: งบกำไรขาดทุน | G93: เครดิต | H93: 1 | I93: 1
A94: 20 | B94: รายได้อื่น | C94: รายได้อื่น | D94: รายได้ | E94: รายได้และค่าใช้จ่าย | F94: งบกำไรขาดทุน | G94: เครดิต | H94: 1 | I94: 1
A95: 30 | B95: ต้นทุนขาย | C95: ต้นทุนขายและการให้บริการ | D95: ค่าใช้จ่าย | E95: รายได้และค่าใช้จ่าย | F95: งบกำไรขาดทุน | G95: เดบิต | H95: 1 | I95: -1
A96: 30 | B96: ต้นทุนขาย > วัตถุดิบและงานระหว่างทำต้นงวด | C96: ต้นทุนขายและการให้บริการ | D96: ค่าใช้จ่าย | E96: รายได้และค่าใช้จ่าย | F96: งบกำไรขาดทุน | G96: เดบิต | H96: 1 | I96: -1
A97: 30 | B97: ต้นทุนขาย > ซื้อวัตถุดิบ | C97: ต้นทุนขายและการให้บริการ | D97: ค่าใช้จ่าย | E97: รายได้และค่าใช้จ่าย | F97: งบกำไรขาดทุน | G97: เดบิต | H97: 1 | I97: -1
A98: 30 | B98: ต้นทุนขาย > ค่าใช้จ่ายอื่นๆในการซื้อวัตถุดิบ | C98: ต้นทุนขายและการให้บริการ | D98: ค่าใช้จ่าย | E98: รายได้และค่าใช้จ่าย | F98: งบกำไรขาดทุน | G98: เดบิต | H98: 1 | I98: -1
A99: 30 | B99: ต้นทุนขาย > ค่าแรงงาน | C99: ต้นทุนขายและการให้บริการ | D99: ค่าใช้จ่าย | E99: รายได้และค่าใช้จ่าย | F99: งบกำไรขาดทุน | G99: เดบิต | H99: 1 | I99: -1
A100: 30 | B100: ต้นทุนขาย > ค่าขนส่ง | C100: ต้นทุนขายและการให้บริการ | D100: ค่าใช้จ่าย | E100: รายได้และค่าใช้จ่าย | F100: งบกำไรขาดทุน | G100: เดบิต | H100: 1 | I100: -1
A101: 30 | B101: ต้นทุนขาย > ค่าใช้จ่ายอื่นๆในการผลิต | C101: ต้นทุนขายและการให้บริการ | D101: ค่าใช้จ่าย | E101: รายได้และค่าใช้จ่าย | F101: งบกำไรขาดทุน | G101: เดบิต | H101: 1 | I101: -1
A102: 30 | B102: ต้นทุนขาย > วัตถุดิบปลายงวด | C102: ต้นทุนขายและการให้บริการ | D102: ค่าใช้จ่าย | E102: รายได้และค่าใช้จ่าย | F102: งบกำไรขาดทุน | G102: เดบิต | H102: -1 | I102: -1
A103: 30 | B103: ต้นทุนขาย > งานระหว่างทำปลายงวด | C103: ต้นทุนขายและการให้บริการ | D103: ค่าใช้จ่าย | E103: รายได้และค่าใช้จ่าย | F103: งบกำไรขาดทุน | G103: เดบิต | H103: -1 | I103: -1
A104: 30 | B104: ต้นทุนขาย > สินค้าคงเหลือต้นงวด | C104: ต้นทุนขายและการให้บริการ | D104: ค่าใช้จ่าย | E104: รายได้และค่าใช้จ่าย | F104: งบกำไรขาดทุน | G104: เดบิต | H104: 1 | I104: -1
... A168: 60 | B168: ค่าใช้จ่ายอื่น | C168: ค่าใช้จ่ายอื่น | D168: ค่าใช้จ่าย | E168: รายได้และค่าใช้จ่าย | F168: งบกำไรขาดทุน | G168: เดบิต | H168: 1 | I168: -1
A169: 70 | B169: ภาษีเงินได้นิติบุคคล | C169: ภาษีเงินได้นิติบุคคล | D169: ต้นทุนทางการเงิน | E169: รายได้และค่าใช้จ่าย | G169: เดบิต | H169: 1 | I169: -1
A170: 80 | B170: ต้นทุนทางการเงิน | C170: ต้นทุนทางการเงิน | D170: ต้นทุนทางการเงิน | E170: รายได้และค่าใช้จ่าย | G170: เดบิต | H170: 1 | I170: -1

Sheet 000
A13: กระดาษทำการสอบบัญชี
A15: =ข้อมูลลูกค้า!B2
D20: งวดตั้งแต่วันที่ | F20: =ข้อมูลลูกค้า!$B$9
D21: ถึงวันที่ | F21: =ข้อมูลลูกค้า!$B$10
B43: บริษัท เคเอสเค แอคเคาน์ติ้ง จำกัด
B44: 9/2130 หมู่บ้านพิมานธานี ซอย 21 ถนนกลางเมือง ตำบลเมืองเก่า อำเภอเมืองขอนแก่น จังหวัดขอนแก่น

Sheet 001
A1: สารบัญ – แฟ้มตรวจสอบประจำปี
A2: ชื่อ | B2: =ข้อมูลลูกค้า!B2 | C2: จัดทำโดย | E2: วันที่ :
A3: รอบบัญชีตั้งแต่ | B3: =ข้อมูลลูกค้า!$B$9 | C3: สอบทาน | E3: วันที่ :
A4: ถึงวันที่ | B4: =ข้อมูลลูกค้า!$B$10
A6: รหัส | B6: เรื่อง | C6: จัดทำ | D6: สอบทาน | E6: มี/เสร็จเรียบร้อย
A7: 100 | B7: การตอบรับงานสอบบัญชี
A8: 101 | B8: แบบประเมินความเสี่ยงก่อนตอบรับงานลูกค้ารายใหม่/ลูกค้ารายเดิม
A9: 102 | B9: หนังสือตอบรับงาน
A10: 103 | B10: การสอบทานงานสอบบัญชีของผู้สอบบัญชีรายก่อน (กรณีเป็นลูกค้าสอบบัญชีปีแรก)
A12: 200 | B12: การวางแผนการตรวจสอบ
A13: 201 | B13: สรุปความเข้าใจในสภาพธุรกิจและกิจการที่ตรวจสอบ
A14: 202 | B14: การกำหนดความมีสาระสำคัญในการวางแผนและการปฏิบัติงานสอบบัญชี
A15: 203 | B15: การวิเคราะห์เปรียบเทียบในขั้นต้น
A16: 204 | B16: การกำหนดงบประมาณ และระยะเวลาในการตรวจสอบ
A17: 205 | B17: การประชุมของผู้ปฏิบัติงานตรวจสอบในช่วงวางแผนการตรวจสอบ
A18: 206 | B18: การประชุมกับผู้บริหารในช่วงวางแผนการตรวจสอบ
A19: 207 | B19: การสื่อสารกับผู้มีหน้าที่ในการกำกับดูแล เช่น คณะกรรมการตรวจสอบ หน่วยงานตรวจสอบภายใน
... A77: 610 | B77: Sign-Off การตรวจสอบโดยผู้สอบบัญชีที่รับผิดชอบงาน

Sheet 101
A2: หนังสือยืนยันความเป็นอิสระและการรักษาความลับ ประจำปี พ.ศ 2562
B4: ความเป็นอิสระ
B5: ข้าพเจ้าขอยืนยันว่าข้าพเจ้าได้ปฏิบัติตามข้อบังคับสภาวิชาชีพบัญชี (ฉบับที่ 19) เรื่องจรรยาบรรณของผู้ประกอบวิชาชีพบัญชี
B6: พ.ศ. 2553 ในหมวดที่ 2 เรื่องความเป็นอิสระ ดังนี้
C8: ในหัวข้อที่ 9 (1) ผู้ประกอบวิชาชีพบัญชีต้องใช้ดุลยพินิจและปฏิบัติงานอย่างเป็นอิสระภายใต้กรอบวิชาชีพบัญชี และ
C9: ในหัวข้อที่ 9 (2) ผู้ประกอบวิชาชีพบัญชีต้องไม่ปฏิบัติงานที่ตนขาดความเป็นอิสระภายใต้กรอบวิชาชีพบัญชี
B11: การรักษาความลับ
B12: ข้าพเจ้าขอยืนยันว่าข้าพเจ้าได้ปฏิบัติตามข้อบังคับสภาวิชาชีพบัญชี (ฉบับที่ 19) เรื่องจรรยาบรรณของผู้ประกอบวิชาชีพบัญชี
B13: พ.ศ. 2553 ในหมวดที่ 4 เรื่องการรักษาความลับ ดังนี้
C15: ในหัวข้อที่ 14 ผู้ประกอบวิชาชีพบัญชีต้องไม่นำข้อมูลที่เป็นความลับขององค์กร ที่ตนได้มาจากการปฏิบัติงานวิชาชีพ
D16: และความสัมพันธ์ในทางธุรกิจ รวมทั้งความลับขององค์กรที่ตนสังกัด ไปเปิดเผยต่อบุคคลที่ไม่มีส่วน
D17: เกี่ยวข้องได้รับทราบ โดยไม่ได้รับอนุญาตจากองค์กร เว้นแต่ในกรณีที่เป็นการเปิดเผยตามสิทธิหรือ
D18: หน้าที่ที่กำหนดไว้ในกฎหมาย หรือในฐานะผู้ประกอบวิชาชีพบัญชี และ
C19: ในหัวข้อที่ 15 ผู้ประกอบวิชาชีพบัญชีต้องไม่นำข้อมูลที่เป็นความลับขององค์กรที่ตนได้มาจากการปฏิบัติงานวิชาชีพ
D20: และความสัมพันธ์ในทางธุรกิจ รวมทั้งความลับขององค์กรที่ตนสังกัด ไปใช้เพื่อประโยชน์ของตนหรือ
D21: บุคคลอื่นโดยมิชอบ
B22: ยกเว้นประเด็นที่กระทบต่อความเป็นอิสระและการรักษาความลับตามเอกสารแนบ ก.
B24: ข้าพเจ้าได้อ่าน ทำความเข้าใจ และขอรับรองว่า ข้อมูลที่ให้ข้างต้นเป็นความจริง
C25: ลงนาม _______________________________________
C26: ชื่อ-สกุล _______________________________________
C27: ตำแหน่ง _______________________________________
C28: ฝ่าย __________________________________________
C29: วันที่ __________________________________________
A35: เอกสารแนบ ก.
C37: · ประเด็นกระทบต่อความเป็นอิสระ
C38: รายละเอียด | F38: สาเหตุที่อาจจะทำให้กระทบต่อ ความเป็นอิสระ | I38: มาตรการป้องกันผลกระทบหรือวิธีการขจัดผลกระทบต่อความเป็นอิสระ
C44: · ประเด็นกระทบต่อการรักษาความลับ
C45: รายละเอียด | F45: สาเหตุที่อาจจะทำให้กระทบต่อ ความเป็นอิสระ | I45: มาตรการป้องกันผลกระทบหรือวิธีการขจัดผลกระทบต่อความเป็นอิสระ
A66: หนังสือยืนยันความเป็นอิสระรายบุคคลเฉพาะบริษัท
B68: ข้าพเจ้าขอยืนยันว่า ข้าพเจ้าจะปฏิบัติตามนโยบายและวิธีปฏิบัติของสำนักงานในเรื่องความเป็นอิสระของ
B69: ผู้ประกอบวิชาชีพบัญชี ซึ่งรวมถึงแนวทางปฏิบัติในเรื่องความเป็นอิสระของผู้ประกอบวิชาชีพบัญชีที่เกี่ยวข้องอื่น
B70: [อาจจะระบุนโยบายหรือแนวทางปฏิบัติที่เกี่ยวข้อง] ต่อ
B71: (“บริษัท”) และกิจการที่เกี่ยวข้องกันของบริษัท (ถ้ามี) ซึ่งรวมถึงในเรื่องดังต่อไปนี้
B73: 1 | C73: ข้าพเจ้าและบุคคลในครอบครัว (ซึ่งหมายถึง คู่สมรส และบุคคลที่อยู่ภายใต้อุปการะของข้าพเจ้า)
C74: ไม่มีส่วนได้เสียทางการเงินโดยทางตรงหรือทางอ้อมที่มีสาระสำคัญในบริษัทหรือกิจการที่เกี่ยวข้องกัน
C75: ของบริษัท (ถ้ามี)
B77: 2 | C77: ข้าพเจ้าและบุคคลในครอบครัว ไม่ซื้อหรือขายหลักทรัพย์ที่ออกโดยบริษัทหรือกิจการที่เกี่ยวข้องกันของบริษัท
C78: (ถ้ามี) ในระหว่างการปฏิบัติงานตรวจสอบและภายในระยะเวลา 6 เดือนหลังจากเสร็จสิ้นการตรวจสอบบริษัท
B80: 3 | C80: ข้าพเจ้าและบุคคลในครอบครัว ไม่มีเงินให้กู้ยืมหรือเงินกู้ยืมจากบริษัทหรือกิจการที่เกี่ยวข้องกันของบริษัท (ถ้ามี)
C81: รวมถึงผู้ถือหุ้นรายใหญ่ ผู้บริหารสำคัญ และกรรมการของบริษัทหรือกิจการที่เกี่ยวข้องกันดังกล่าว (โดยที่บริษัท
...

Sheet 102
B2: คำอธิบาย
B3: แบบประเมินความเสี่ยงก่อนตอบรับงานจากลูกค้ารายเดิม เป็นเอกสารที่ต้องจัดทำขึ้นในช่วงการวางแผนการตรวจสอบในแต่ละปี
B4: เพื่อใช้ในการพิจารณาว่าลูกค้ารายเดิมนั้นยังมีความเหมาะสมในการตรวจสอบโดยสำนักงานต่อไปอีกหรือไม่
C6: ชื่อกิจการ | D6: =ข้อมูลลูกค้า!$B$2
C7: งวดบัญชี | D7: ตั้วแต่วันที่ | E7: =ข้อมูลลูกค้า!$B$9 | F7: ถึงวันที่ | G7: =ข้อมูลลูกค้า!$B$10
B9: 1. | C9: ข้อมูลทั่วไป
B10: 1.1 | C10: ประเภทของกิจการ | E10: =ข้อมูลลูกค้า!$B$6
B11: 1.2 | C11: รายชื่อผู้ถือหุ้น | E11: มี หรือ อาจมีข้อสงสัยเกี่ยวกับการทำผิดกฎหมาย
C12: ดู บอจ.5 | E12: ไม่มี
B14: 1.3 | C14: ข้อมูลทางการเงินล่าสุด
C15: ดู งบทดลอง
B17: 2. | C17: ข้อพิจารณา
C19: คำถาม | H19: ความเห็น
C20: 2.1 ลูกค้าเป็นกิจการที่มีส่วนได้เสียสาธารณะหรือไม่ | H20: ไม่
C21: 2.2 สำนักงานได้พิจารณาถึงความซื่อสัตย์สุจริตของลูกค้าแล้ว และ | H21: ใช่
C22: ไม่มีข้อมูลที่นำไปสู่ข้อสรุปว่าลูกค้าขาดความซื่อสัตย์สุจริต ใช่หรือไม่
C23: 2.3 สำนักงานและกลุ่มผู้ปฏิบัติงานมีความรู้ความสามารถที่จำเป็นในการปฏิบัติ | H23: ใช่
C24: งานนี้หรือไม่
C25: 2.4 สำนักงานมีทรัพยากรและเวลาในการปฏิบัติงานได้ทันตามกำหนดหรือไม่ | H25: ทัน
C26: 2.5 สำนักงานได้พิจารณาว่า
C27: • งาน Audit : ไม่มีข้อมูลและเหตุการณ์ที่ทำให้ขาดความเป็นอิสระ ใช่หรือไม่ | H27: ใช่ (งาน audit)
C28: • งาน Non-Audit เช่น งานบริการที่ไม่เกี่ยวกับงานตรวจสอบหรือให้ | H28: ไม่มีงาน non audit
C29: ความเชื่อมั่น หรืองานอื่นตามที่ตกลงร่วมกัน :
C30: ไม่มีข้อมูลและเหตุการณ์ที่ทำให้ขาดความเป็นอิสระ ใช่หรือไม่
C31: 2.6 สำนักงานไม่มีความขัดแย้งทางผลประโยชน์กับลูกค้า ใช่หรือไม่ | H31: ใช่
C32: (ถ้ามีความขัดแย้งทางผลประโยชน์เกิดขึ้น จะจัดการได้อย่างไร)
C33: 2.7 มีประเด็นที่สำคัญเกี่ยวกับการสอบบัญชีในปีก่อนซึ่งเป็นความเห็นขัดแย้ง | H33: ไม่
C34: กับผู้บริหารและอาจมีผลกระทบต่องานตรวจสอบในปีปัจจุบันหรือไม่
C35: 2.8 มีเหตุการณ์ปัจจุบันที่มีผลกระทบต่อการดำเนินธุรกิจ การบริหารงานของลูกค้า | H35: ไม่
C36: และความเสี่ยงที่ได้จากการประเมินหรือไม่
C37: 2.9 สำนักงานไม่มีปัญหาเกี่ยวกับการกำหนดค่าบริการ และการเก็บค่าบริการ | H37: ใช่
C38: ใช่หรือไม่
B42: สรุปการตัดสินใจ
C43: คงไว้ซึ่งความสัมพันธ์กับลูกค้ารายเดิม
C44: ยุติความสัมพันธ์กับลูกค้ารายเดิม
B46: การใช้ EQCR ในงาน
C47: ใช้ โปรดระบุชื่อ.............................................
C48: ไม่ใช้
B50: ข้อมูลเกี่ยวกับค่าสอบบัญชี
C51: ประมาณการค่าสอบบัญชี | F51: =ข้อมูลลูกค้า!$B28
...

Sheet 103
A2: หนังสือตอบรับงานสอบบัญชี
B4: เรียน | C4: กรรมการ | E4: =ข้อมูลลูกค้า!$B$2
D6: ตามที่ท่านมีความประสงค์ที่จะให้ข้าพเจ้าตรวจสอบงบการเงินของ | I6: =ข้อมูลลูกค้า!$B$2
B7: ซึ่งประกอบด้วย งบฐานะการเงิน ณ วันที่ | G7: =ข้อมูลลูกค้า!$B$10 | H7: งบกำไรขาดทุน และ งบการเปลี่ยนแปลง
B8: ส่วนของผู้ถือหุ้น สำหรับรอบบัญชีตั้งแต่วันที่ | G8: =ข้อมูลลูกค้า!$B$9 | H8: ถึง | I8: =ข้อมูลลูกค้า!$B$10 | J8: รวมถึงข้อมูลนโยบาย
B9: การบัญชีที่มีสาระสำคัญและคำอธิบายเพิ่มเติมอื่น ข้าพเจ้าขอยืนยันการรับงานและความเข้าใจของข้าพเจ้าเกี่ยวกับงานสอบบัญชีนี้
B10: ตามความหมายในหนังสือฉบับนี้ การตรวจสอบของข้าพเจ้ามีวัตถุประสงค์ในการแสดงความเห็นของข้าพเจ้าต่องบการเงิน
D12: ข้าพเจ้าจะปฏิบัติงานตรวจสอบโดยสอดคล้องกับมาตรฐานการสอบบัญชี มาตรฐานการสอบบัญชีเหล่านั้นกำหนด
B13: ให้ข้าพเจ้าต้องปฏิบัติตามข้อกำหนดด้านจรรยาบรรณ รวมถึงวางแผนและปฏิบัติการตรวจสอบเพื่อให้ได้ความเชื่อมั่นอย่าง
B14: สมเหตุสมผลว่างบการเงินปราศจากการแสดงข้อมูลที่ขัดต่อข้อเท็จจริงอันเป็นสาระสำคัญหรือไม่ การตรวจสอบรวมถึงการใช้
B15: วิธีตรวจสอบเพื่อให้ได้มาซึ่งหลักฐานการสอบบัญชีเกี่ยวกับจำนวนเงินและการเปิดเผยข้อมูลในงบการเงิน วิธีการตรวจสอบที่
B16: เลือกใช้ขึ้นอยู่กับดุลยพินิจของผู้สอบบัญชี ซึ่งรวมถึงการประเมินความเสี่ยงจากการแสดงข้อมูลที่ขัดต่อข้อเท็จจริงอันเป็น
B17: สาระสำคัญของงบการเงิน ไม่ว่าจะเกิดจากการทุจริตหรือข้อผิดพลาดการตรวจสอบรวมถึงการประเมินความเหมาะสมของ
B18: นโยบายการบัญชีที่ใช้และความสมเหตุสมผลของประมาณการทางบัญชี ที่จัดทำขึ้นโดยผู้บริหาร รวมทั้งการประเมินการนำเสนอ
B19: โดยรวมของงบการเงิน
D21: เนื่องจากข้อจำกัดสืบเนื่องของการตรวจสอบ รวมถึงข้อจำกัดสืบเนื่องของการควบคุมภายใน ทำให้มีความเสี่ยงซึ่ง
B22: ไม่อาจหลีกเลี่ยงได้ที่การแสดงข้อมูลที่ขัดต่อข้อเท็จจริงอันเป็นสาระสำคัญอาจไม่ถูกค้นพบ แม้ว่าการตรวจสอบได้ถูกวางแผน
B23: และปฏิบัติอย่างเหมาะสมโดยสอดคล้องกับมาตรฐานการสอบบัญชี
D25: ในการประเมินความเสี่ยงของข้าพเจ้า ข้าพเจ้าพิจารณาการควบคุมภายในที่เกี่ยวข้องกับการจัดทำงบการเงินของ
B26: กิจการเพื่อออกแบบวิธีการตรวจสอบที่เหมาะสมกับสถานการณ์ แต่ไม่ใช่เพื่อวัตถุประสงค์ในการแสดงความคิดเห็นต่อ
B27: ประสิทธิผลของการควบคุมภายในของกิจการ อย่างไรก็ตามข้าพเจ้าจะแจ้งให้ท่านทราบเป็นลายลักษณ์อักษรเกี่ยวกับ
B28: ข้อบกพร่องที่สำคัญของการควบคุมภายในที่เกี่ยวข้องกับการตรวจสอบงบการเงินที่ข้าพเจ้าพบระหว่างการตรวจสอบ
D30: การตรวจสอบถูกปฏิบัติตามหลักการที่ว่าผู้บริหารรับทราบและเข้าใจว่าตนเองมีความรับผิดชอบในเรื่องดังต่อไปนี้
D31: (ก) เรื่องการจัดทำและการนำเสนองบการเงินโดยถูกต้องตามที่ควรโดยสอดคล้องกับมาตรฐานการรายงาน
B32: ทางการเงิน
D33: (ข) เรื่องการควบคุมที่ผู้บริหารพิจารณาว่าจำเป็นเพื่อให้สามารถจัดทำงบการเงินโดยปราศจากการแสดงข้อมูลที่
B34: ขัดต่อข้อเท็จจริงอันเป็นสาระสำคัญไม่ว่าจะเกิดจากการทุจริตหรือข้อผิดพลาด และ
D37: (ค) เรื่องการจัดเตรียมสิ่งต่อไปนี้ให้แก่ข้าพเจ้า
E38: (1) การเข้าถึงข้อมูลทั้งหมดที่ซึ่งผู้บริหารตระหนักว่าเกี่ยวข้องกับการจัดทำงบการเงินเช่น การบันทึกบัญชี
E39: เอกสารหลักฐาน และข้อมูลอื่น
E40: (2) ข้อมูลเพิ่มเติมที่ข้าพเจ้าอาจร้องขอจากผู้บริหารเพื่อประโยชน์ในการตรวจสอบ และ
E41: (3) การเข้าถึงบุคคลต่าง ๆ ภายในกิจการได้อย่างไม่มีข้อจำกัด ซึ่งข้าพเจ้าพิจารณาว่าจำเป็นที่จะต้องได้รับ
E42: หลักฐานการสอบบัญชีจากบุคคลเหล่านี้
D44: เพื่อเป็นส่วนหนึ่งในกระบวนการตรวจสอบของข้าพเจ้า ข้าพเจ้าจะขอคำยืนยันที่เป็นลายลักษณ์อักษรจากกรรมการ
B45: เกี่ยวกับคำรับรองที่เกี่ยวข้องกับการตรวจสอบ
D47: ทั้งนี้ ข้าพเจ้าจะคิดค่าธรรมเนียมในการสอบบัญชีเป็นจำนวนเงินรวมทั้งสิ้น
G48: ='102'!$F$51 | H48: บาท
D50: โปรดลงนามและส่งคู่ฉบับของหนังสือฉบับนี้ที่แนบมาคืนข้าพเจ้า เพื่อยืนยันการรับทราบและความเห็นชอบของท่าน
B51: เกี่ยวกับ การตรวจสอบงบการเงินของข้าพเจ้ารวมถึงความรับผิดชอบที่เกี่ยวข้องของข้าพเจ้า
G54: ลงชื่อ...........................................……
...

Sheet 202
A1: =ข้อมูลลูกค้า!B2
A2: งบตั้งแต่วันที่ | B2: =ข้อมูลลูกค้า!$B$9 | C2: ถึง | D2: =ข้อมูลลูกค้า!$B$10
A3: การวางแผนการตรวจสอบโดยรวม
A5: ขอบเขต
A6: ขอบเขตการตรวจสอบบัญชีของ | C6: =ข้อมูลลูกค้า!$B$2
A7: ตั้งแต่วันที่ | B7: =ข้อมูลลูกค้า!B9 | C7: ถึง | D7: =ข้อมูลลูกค้า!$B$10
A8: มีจุดประสงค์เพื่อดูว่า งบการเงินได้จัดทำขึ้นตามมาตรฐานการรายงานทางการเงินสำหรับกิจการที่ไม่มีส่วนได้เสียสาธารณะ
A9: อย่างเหมาะสมหรือไม่
A11: =ข้อมูลลูกค้า!A56
B12: =ข้อมูลลูกค้า!B56
B13: =ข้อมูลลูกค้า!B57
A15: =ข้อมูลลูกค้า!A59
B16: =ข้อมูลลูกค้า!B59
B17: =ข้อมูลลูกค้า!B60
A18: =ข้อมูลลูกค้า!A62
B19: =ข้อมูลลูกค้า!B62
B20: =ข้อมูลลูกค้า!B63
A21: =ข้อมูลลูกค้า!A65
B22: =ข้อมูลลูกค้า!B65
B23: =ข้อมูลลูกค้า!B66
A25: กลยุทธ์การตรวจสอบโดยรวม
A26: 1. ตรวจสอบงบการเงินโดยผู้สอบบัญชี | C26: =ข้อมูลลูกค้า!$B$20 | D26: คน
B27: =ข้อมูลลูกค้า!#REF!
B28: =ข้อมูลลูกค้า!#REF!
B29: =ข้อมูลลูกค้า!B21
B30: =ข้อมูลลูกค้า!B24
B31: =ข้อมูลลูกค้า!B25
A32: 2. ช่วงเวลาที่ทำการตรวจสอบ
A33: ตั้งแต่วันที่ | B33: =ข้อมูลลูกค้า!B26 | C33: ถึง | D33: =ข้อมูลลูกค้า!B27
B34: จำนวน | C34: =ข้อมูลลูกค้า!B29 | D34: ชั่วโมง
A35: 3. วิธีการตรวจสอบที่ใช้
B36: =ข้อมูลลูกค้า!B31
B37: =ข้อมูลลูกค้า!B32
A38: เนื่องจาก | B38: =ข้อมูลลูกค้า!B33
B39: =ข้อมูลลูกค้า!B34
B40: =ข้อมูลลูกค้า!B35
A41: 4. คาดการณ์งบประมาณในการตรวจสอบทั้งสิ้น | D41: =ข้อมูลลูกค้า!B37 | E41: บาท
A43: การกำหนดความมีสาระสำคัญ
A45: ผู้ใช้งบการเงินหลัก
B46: =ข้อมูลลูกค้า!B41
...

Sheet 203 TB (2)
A1: =ข้อมูลลูกค้า!B2
A2: งบตั้งแต่วันที่ | B2: =ข้อมูลลูกค้า!$B$9 | C2: ถึง | D2: =ข้อมูลลูกค้า!$B$10
A3: TB วิเคราะห์การเปลี่ยนแปลง

Sheet 301
A1: =ข้อมูลลูกค้า!B2
A2: งบตั้งแต่วันที่ | B2: =ข้อมูลลูกค้า!$B$9 | C2: ถึง | D2: =ข้อมูลลูกค้า!$B$10
A3: การประเมินความเสี่ยง
A5: ขั้นตอนการประเมินความเสี่ยง
A6: 1. สอบถามและเก็บข้อมูลจาก
B7: 1.1 ผู้บริหาร พนักงานและผู้จัดทำบัญชี
B8: 1.2 ค้นหาข้อมูลทางอินเตอร์เนต เกี่ยวกับสภาพอุตสาหกรรม ข่าวของกิจการ และกฎหมายที่เกี่ยวข้อง
B9: 1.3 สอบทานเอกสารภายใน
A11: Assertion | B11: Completeness | C11: C
B12: Accuracy | C12: A
B13: Existence & Occurance | C13: E
B14: Right & Obligation | C14: R
B15: Cut-off | C15: CO
B16: Valuation & Allocation | C16: V
B17: Presentation & Disclosure | C17: P
A19: 2.การประเมินความเสี่ยง
A20: สภาพแวดล้อมของกิจการ | B20: =ข้อมูลลูกค้า!B56
A25: เหตุการณ์ / สาเหตุของความเสี่ยง | B25: ความเสี่ยง | C25: Assertion | D25: การประเมินความเสี่ยง | E25: เป็นความเสี่ยงที่มี นัยยะสำคัญใช่หรือไม่
A26: กิจการไม่มีการควบคุมภายในที่แน่ชัด เจ้าของกิจการเป็นผู้ตัดสินใจทุกอย่าง เนื่องจากเป็นกิจการขนาดเล็ก | B26: การบันทึกบัญชีไม่ถูกต้อง | C26: All | D26: มีโอกาสเกิดขึ้นสูง และมีผลกระทบกับงบการเงินมาก | E26: ใช่
A27: กิจการขนาดเล็ก มักมีความต้องการเสียภาษีน้อย | B27: บันทึกรายได้ไม่ครบถ้วน บันทึกค่าใช้จ่ายสูงกว่าความเป็นจริง | C27: C A | D27: โอกาสในการบันทึกรายได้ไม่ครบถ้วนมีน้อย แต่โอกาสในการบันทึกค่าใช้จ่ายสูงกว่าความเป็นจริงเป็นไปได้สูง ส่งผลกระทบกับงบการเงินมาก | E27: ใช่

Sheet 302
A1: =ข้อมูลลูกค้า!B2
A2: งบตั้งแต่วันที่ | B2: =ข้อมูลลูกค้า!$B$9
A3: ถึงวันที่ | B3: =ข้อมูลลูกค้า!$B$10
A4: แผนการตรวจสอบเพื่อตอบสนองต่อความเสี่ยงที่มีนัยยะสำคัญ
B7: ความเสี่ยงที่มีนัยยะสำคัญ | C7: การควบคุมกิจการภายใน | D7: แผนการตรวจสอบเพื่อตอบสนองต่อความเสี่ยง
B8: มีความเสี่ยงจากการทุจริตในการรับรู้รายได้ | C8: กิจการไม่มีการควบคุมภายใน ผู้จัดทำบัญชี (ซึ่งเป็นผู้รับทำบัญชีอิสระ) จะทำการตรวจสอบรายได้ / ใบหักภาษี ณ ที่จ่าย / ก่อนที่จะทำการบันทึกบัญชี รวมถึงการสอบทานการเคลื่อนไหวของบัญชีเงินฝากธนาคาร เพื่อตรวจสอบรายได้ที่อาจจะไม่ได้รับรู้ | D8: 1. ทดสอบรายการในบัญชีรายได้ ทุกรายการ เนื่องจากมีรายการจำนวนไม่มาก 2. ตรวจสอบรายการเดินบัญชีธนาคาร 3. ตรวจสอบจำนวนสินค้าคงเหลือ
B9: ความเสี่ยงจากการที่ผู้บริหารแทรกแซงการควบคุม เพื่อบิดเบือนข้อมูลในงบการเงิน | C9: ไม่มี | D9: 1.ทดสอบรายการบันทึกค่าใช้จ่ายค้างจ่าย 2. ทดสอบรายการค่าใช้จ่ายที่มีจำนวนผิดปกติ
B10: - กิจการขนาดเล็ก มักจะต้องการเสียภาษีน้อย

Sheet 401
A1: =ข้อมูลลูกค้า!B2
A2: งบตั้งแต่วันที่ | B2: =ข้อมูลลูกค้า!$B$9
A3: ถึงวันที่ | B3: =ข้อมูลลูกค้า!$B$10
A4: การทำความเข้าใจและทดสอบระบบการควบคุมภายใน
A6: กิจการเพิ่งจัดตั้ง ยังไม่มีการดำเนินธุรกิจ
A8: สำหรับการบันทึกบัญชี กิจการได้จ้างผู้จัดทำบัญชีอิสระ บันทึกรายการ และจัดทำงบการเงิน
A9: ซึ่งรายการในระหว่างปีนั้น มีจำนวนไม่มาก
A10: โดยโปรแกรมในการบันทึกบัญชี เป็น software ชื่อ Express
A11: ซึ่งผู้จัดทำบัญชีเป็นผู้เลือกใช้ โดยจากการสอบถามและสอบทานการใช้งาน โปรแกรมมีประสิทธิภาพที่ดี และ
A12: ตัวโปรแกรมมีการสำรองข้อมูลอย่างสม่ำเสมอ
A14: ผู้สอบบัญชีจึงไม่ได้ทำการทดสอบการควบคุมระบบภายใน และใช้วิธีตรวจสอบเนื้อหาสาระทั้งหมด

Sheet 601
H3: =ข้อมูลลูกค้า!$B$39
B5: เรียน | C5: ผู้สอบบัญชีของ | F5: =ข้อมูลลูกค้า!$B$2
D7: หนังสือรับรองฉบับนี้ให้ไว้เพื่อประโยชน์ของท่านในการตรวจสอบงบการเงินของ | I7: =ข้อมูลลูกค้า!$B$2
B8: สำหรับงวดบัญชีสิ้นสุดวันที่ | F8: =ข้อมูลลูกค้า!$B$10 | G8: เพื่อแสดงความเห็นว่างบการเงินดังกล่าว แสดงฐานะการเงิน ณ วันที่
B9: =ข้อมูลลูกค้า!$B$10 | F9: ผลการดำเนินงาน และการเปลี่ยนแปลงส่วนของผู้ถือหุ้นสำหรับงวดบัญชีตั้งแต่วันที่ | J9: =ข้อมูลลูกค้า!$B$9
B10: ถึง | C10: =ข้อมูลลูกค้า!$B$10 | F10: และหมายเหตุสรุปนโยบายการบัญชีที่สำคัญ และหมายเหตุเรื่องอื่นๆ เพื่อวัตถุประสงค์ในการให้ข้อสรุปว่า
B11: พบสิ่งที่เป็นเหตุให้เชื่อว่างบการเงินดังกล่าวไม่ได้จัดทำขึ้นตามมาตรฐานการรายงานการเงินหรือไม่
B13: ข้าพเจ้าขอรับรองว่า ข้าพเจ้ามีความรับผิดชอบต่อเรื่องต่างๆ มีดังนี้
C14: 1. | D14: ข้าพเจ้ามีความรับผิดชอบต่อความเหมาะสมของการแสดงรายการในงบการเงิน ซึ่งแสดงฐานะการเงิน ผลการดำเนินงาน
D15: และการเปลี่ยนแปลงส่วนของผู้ถือหุ้น โดยถูกต้องตามแม่บทการบัญชีและมาตรฐานการรายงานทางการเงินที่เกี่ยวข้อง
C16: 2. | D16: ข้าพเจ้ามีความรับผิดชอบในการออกแบบและนำการควบคุมภายในไปปฏิบัติตามเพื่อป้องกันและตรวจสอบการทุจริต
D17: และข้อผิดพลาด
C18: 3. | D18: ข้าพเจ้ามีความรับผิดชอบในการกำหนดและดูแลระบบการควบคุมภายในที่มีประสิทธิผลในการจัดทำงบการเงิน
B20: ข้าพเจ้าขอรับรองว่า จากการใช้ความรู้ความสามารถอย่างเต็มที่ ในการนำเสนอข้อมูลดังต่อไปนี้เพื่อการตรวจสอบของท่าน
D22: งบการเงินตามที่กล่าวข้างต้นได้จัดทำขึ้นตามมาตรฐานการรายงานทางการเงิน ภายใต้พระราชบัญญัติวิชาชีพบัญชี
B23: พ.ศ. 2547 ตามประกาศสภาวิชาชีพ ฉบับที่ 48/2565 ลงวันที่ 30 พฤศจิกายน 2565 เรื่อง “มาตรฐานรายงานทางการเงินสำหรับกิจการที่
B24: ไม่มีส่วนได้เสียสาธารณะ” (NPAEs) รวมถึงการตีความและแนวปฏิบัติทางการบัญชีที่ประเทศใช้โดยสภาวิชาชีพบัญชี ทั้งนี้ฝ่ายบริหาร
B25: ของบริษัทได้ประเมินแล้วเห็นว่าการถือปฏิบัติตามมาตรฐานการบัญชี มาตรฐานการรายงานทางการเงิน การตีความมาตรฐานการบัญชี
B26: และแนวปฏิบัติทางบัญชีสำหรับกิจการที่ไม่มีส่วนได้เสียสาธารณะดังกล่าวข้างต้นไม่มีผลกระทบอย่างเป็นสาระสำคัญต่องบการเงินนี้
D27: และแสดงรายการในงบการเงินเพื่อให้เป็นไปตมข้อกำหนดประกาศกรมพัฒนาธุรกิจการค้าโดยกระทรวงพาณิชย์
B28: ลงวันที่ 27 ตุลาคม 2566 เรื่อง กำหนดรายการย่อที่ต้องมีในงบการเงิน พ.ศ. 2566
B30: ข้าพเจ้าได้จัดเอกสารหลักฐานและข้อมูลดังต่อไปนี้ให้ท่านได้ตรวจสอบครบถ้วนแล้ว ดังนี้
C31: 1. | D31: บัญชี เอกสาร หลักฐาน ข้อมูลทางการเงิน และข้อมูลอื่นที่เกี่ยวข้องรายงานการประชุมคณะกรรมการและ
B32: คณะกรรมการบริหาร ตลอดจนรายงานการประชุมผู้ถือหุ้น รวมทั้งสรุปผลการประชุม ในกรณีที่ยังไม่ได้จัดทำรายงานการประชุม
B33: (ตามเอกสารแนบ 1)
C35: 2. | D35: จาก | E35: =ข้อมูลลูกค้า!$B$10 | G35: จนถึงในที่ตามจดหมายฉบับนี้ ไม่มีการประชุมอื่นใด ที่ต้องจัดทำรายงานการประชุม
B36: นอกจากที่ได้จัดให้แก่ท่าน
C37: 3. | D37: บริษัทไม่ได้รับหนังสือแจ้งจากหน่วยราชการอันมีผลอย่างมีสาระสำคัญต่องบการเงินเพราะมิได้ปฏิบัติตาม ข้อบังคับ หรือ
B38: กฎหมายซึ่งรวมถึงการถูกชดเชยหรือถูกเรียกประเมินภาษีอากรหรือมีหนี้สินที่อาจจะเกิดขึ้นในภายหน้า
C39: 4. | D39: ข้าพเจ้าเชื่อว่าผลกระทบของการละเว้นการเปิดเผยข้อมูลไม่เป็นสาระสำคัญทั้งเชิงปริมาณและเชิงคุณภาพ ทั้งรายการ
B40: เดียวและรวมกัน และรายการผิดพลาดที่ไม่ได้ถูกแก้ไขระหว่างที่ท่านปฏิบัติงานสอบทานที่มีผลกระทบกับงบการเงินในปีปัจจุบันไม่เป็น
B41: สาระสำคัญต่องบการเงินโดยรวม ทั้งรายการเดียวและรวมกัน
C42: 5. | D42: ข้าพเจ้าได้เปิดเผยให้ท่านทราบถึงข้อเท็จจริงที่มีนัยสำคัญทั้งหมดที่เกี่ยวกับการทุจริตที่พบ หรือสงสัยว่าจะมีผลกระทบ
B43: ต่อบริษัทแล้ว
C44: 6. | D44: ข้าพเจ้าได้เปิดเผยให้ท่านทราบถึงผลการประเมินความเสี่ยงของข้าพเจ้าในส่วนที่อาจทำให้ งบการเงินแสดงข้อมูลที่ขัดต่อ
B45: ข้อเท็จจริงอันเป็นสาระสำคัญอันมีผลเนื่องมาจากการทุจริตแล้ว
C46: 7. | D46: บริษัทได้ปฏิบัติตามเงื่อนไขของสัญญาทั้งหมด โดยไม่มีการละเมิดสัญญา และข้อผูกพันต่าง ๆ อันอาจมีผลกระทบอย่าง
B47: มีสาระสำคัญต่องบการเงิน
C48: 8. | D48: บริษัทมีกรรมสิทธิ์โดยสมบูรณ์ในทรัพย์สินทั้งหมดของบริษัทอย่างถูกต้องตามกฎหมาย และไม่มีภาระผูกพัน ไม่มีสิทธิ์
B49: ยึดหน่วงหรือ จำนำหรือจำนองหรือวางทรัพย์สินนั้นเป็นประกันหนี้ เว้นแต่ที่ได้เปิดเผยไว้ในหมายเหตุประกอบงบการเงิน
...

Sheet 608
A2: สรุปผลการตรวจสอบและประเด็นการตรวจสอบบัญชีโดยรวม
B4: เสนอ | C4: กรรมการ | F4: =ข้อมูลลูกค้า!$B$2
C6: การตรวจสอบของข้าพเจ้าตามมาตรฐานการสอบบัญชี ข้าพเจ้าได้ใช้ดุลยพินิจและการสังเกตและสงสัยเยี่ยงผู้ประกอบวิชาชีพ
B7: ตลอดการตรวจสอบ โดยข้าพเจ้าสรุปผลการตรวจสอบ ปี | H7: =+ข้อมูลลูกค้า!B1 | I7: โดยรวมดังนี้
B9: * | C9: ระบุและประเมินความเสี่ยงที่อาจเกิดขึ้นจากการทุจริตหรือข้อผิดพลาดและทำความเข้าใจในระบบการควบคุมภายในและ
C10: โครงสร้างองค์กรของกิจการพบว่ากิจการเป็นกิจการเจ้าของคนเดียว หรือ กลุ่มผู้บริหารเพียงกลุ่มเดียว อีกทั้งกิจการนั้น
C11: เป็นกิจการขนาดเล็ก และ ผู้มีหน้าที่ในการกำกับดูแลเป็นกลุ่มบุคคลเดียวกับผู้รับผิดชอบในการจัดทำงบการเงิน
C12: (ผู้บริหารมีหน้าที่ในการจัดทำงบการเงิน) ซึ่งตามโครงสร้างของกิจการนั้นยังไม่มีคณะกรรมการการตรวสอบ(Audit Committee)
C13: และยังไม่มีการจัดตั้งแผนกตรวจสอบภายใน(Internal Audit) หรือแต่งตั้งผู้มีหน้าที่ในการกำกับดูแลอื่นเพื่อให้เข้ามามีบทบาท
C14: และรับผิดชอบในการจัดทำงบการเงินแต่อย่างใดโดยผู้ที่ใช้งบการเงินเป็นหลักนั้นจะเป็นกลุ่มบริหารของกิจการเอง เนื่องจาก
C15: กิจการเป็นกิจการขนาดเล็ก จึงไม่ได้มีระบบควบคุมภายในที่ซับซ้อน แต่อย่างใด ข้าพเจ้าจึงออกแบบวิธีการตรวจสอบโดยเน้นไปที่
C16: ตรวจสอบเอกสารประกอบรายการบันทึกบัญชี ส่งเอกสารหนังสือยืนยอด ตรวจสอบรายการหรือเหตุการณ์ต่างๆหลังสิ้นงวด
C17: ในรายงานทางการเงินตรวจสอบการตัดยอด (Cut-off) ตรวจสอบการจับคู่รายการรายได้และค่าใช้จ่าย ตรวจสอบการกระทบ
C18: ยอดรายการและทำการวิเคราะห์เปรียบเทียบรายการต่างๆในรายงานทางการเงินรวมทั้งวิธีการตรวจสอบอื่นๆตามมาตรฐาน
C19: การสอบบัญชี เป็นหลัก ทั้งนี้ความเสี่ยงในประเด็นของการบันทึกบัญชีไม่ครบถ้วนนั้น ข้าพเจ้าได้ทำการขอหนังสือรับรอง
C20: การตรวจสอบบัญชีจากผู้บริหาร เพื่อให้คำรับรองข้อมูลในรอบปีบัญชีที่ข้าพเจ้าตรวจสอบ ผู้บริหารได้ทำการลงบันทึกบัญชีครบถ้วน
C21: รวมทั้งส่งเอกสารประกอบการบันทึกบัญชีและเอกสารทั้งหมดที่กิจการมีให้ข้าพเจ้าตรวจสอบอย่างครบถ้วนแล้ว
B23: * | C23: พบว่าจากการประเมินความเหมาะสมของนโยบายการบัญชีที่ผู้บริหารใช้และความสมเหตุสมผลของประมาณการทางบัญชีและ
C24: การเปิดเผยข้อมูลที่เกี่ยวข้องซึ่งจัดทำขึ้นโดยผู้บริหาร ซึ่งพบว่ากิจการการเปิดเผยและประมาณการบัญชีที่เหมาะสมและครบถ้วน
C25: พอควร
B27: * | C27: ในรอบปีปัจจุบันกิจการยังไม่มีข้อบ่งชี้หรือความเสี่ยงในเรื่องการดำเนินงานต่อเนื่องของกิจการและความไม่แน่นอนที่มีสาระสำคัญ
C28: แต่อย่างใด
B34: * | C34: ข้าพเจ้าพบว่ากิจการมีการจ่ายค่าใช้จ่ายต่างๆจากบัญชีส่วนตัวของกรรมการและมีการยืมเงินกรรมการ
C35: ซึ่งการจ่ายค่าใช้จ่าย ผ่านบัญชีส่วนตัวนั้นถือเป็นจุดอ่อนในการควบคุมภายในของกิจการ ข้าพเจ้าจึงเรียนมาให้ทางผู้บริหาร
C36: ทำการแก้ไขจุดอ่อนการควบคุมภายในดังกล่าว โดยทำการจ่ายค่าใช้จ่ายผ่าน Bank Statement ของกิจการเท่านั้น
C37: ในกรณีที่กิจการยืมหรือคืนเงินกู้แก่กรรมการ ควรกระทำผ่านบัญชีธนาคารของกิจการเท่านั้น
B39: * | C39: ข้าพเจ้าพบว่า แม้ว่ากิจการจะประสบปัญหาในการขายสินค้า แต่ยังมีการจ่ายเงินเดือนตามปกติโดยผู้รับเงินเดือน เป็นกรรมการ
C40: และผู้ถือหุ้นของบริษัท การจ่ายเงินเดือน มีการนำส่งประกันสังคมครบถ้วน แต่อย่างไรก็ดี ค่าใช้จ่ายส่วนนี้อาจพิจารณา
C41: บวกกลับในการคำนวณภาษีเงินได้นิติบุคคล
B44: ประเด็นที่ข้าพเจ้าสื่อสารกับผู้บริหารเกี่ยวกับผลตรวจสอบโดยรวมของรอบปีบัญชีปัจจุบันนี้ตามข้อมูลที่ข้าพเจ้าแสดงในข้างต้นนี้
B46: ลงนาม..................................................... | H46: ......................................................
B47: =(ข้อมูลลูกค้า!$B$13) | H47: =+ข้อมูลลูกค้า!B18
B48: กรรมการ | H48: ผู้สอบบัญชีรับอนุญาต
A49: (ประทับตราบริษัท)
